Workbook

Sheet Rangliste
B2: Rg | D2: Name | E2: SpU | F2: S | G2: U | H2: N | I2: Pkt | K2: Tore | L2: Gegentore | M2: Tordiff. | N2: Sp | O2: A | P2: Pkt/Sp+A
B3: 1 | D3: Harry Sch. | E3: 10 | F3: ='Rangliste (2)'!F13 -> 20 | G3: ='Rangliste (2)'!G13 -> 2 | H3: ='Rangliste (2)'!H13 -> 15 | I3: ='Rangliste (2)'!I13 -> 62 | K3: ='Rangliste (2)'!K13 -> 117 | L3: ='Rangliste (2)'!L13 -> 100 | M3: ='Rangliste (2)'!M13 -> 17 | N3: ='Rangliste (2)'!O13 -> 37 | O3: ='Rangliste (2)'!P13 -> 1.85 | P3: ='Rangliste (2)'!Q13 -> 3.5256757
B4: 2 | D4: Viktor | E4: 3 | F4: ='Rangliste (2)'!F19 -> 18 | G4: ='Rangliste (2)'!G19 -> 3 | H4: ='Rangliste (2)'!H19 -> 13 | I4: ='Rangliste (2)'!I19 -> 57 | K4: ='Rangliste (2)'!K19 -> 104 | L4: ='Rangliste (2)'!L19 -> 95 | M4: ='Rangliste (2)'!M19 -> 9 | N4: ='Rangliste (2)'!O19 -> 34 | O4: ='Rangliste (2)'!P19 -> 1.7 | P4: ='Rangliste (2)'!Q19 -> 3.3764706
B5: 3 | D5: Franz | E5: 8 | F5: ='Rangliste (2)'!F7 -> 16 | G5: ='Rangliste (2)'!G7 -> 3 | H5: ='Rangliste (2)'!H7 -> 17 | I5: ='Rangliste (2)'!I7 -> 51 | K5: ='Rangliste (2)'!K7 -> 98 | L5: ='Rangliste (2)'!L7 -> 103 | M5: ='Rangliste (2)'!M7 -> -5 | N5: ='Rangliste (2)'!O7 -> 36 | O5: ='Rangliste (2)'!P7 -> 1.8 | P5: ='Rangliste (2)'!Q7 -> 3.2166667
B6: 4 | D6: Gerhard C. | E6: 4 | F6: ='Rangliste (2)'!F9 -> 16 | G6: ='Rangliste (2)'!G9 -> 3 | H6: ='Rangliste (2)'!H9 -> 14 | I6: ='Rangliste (2)'!I9 -> 51 | K6: ='Rangliste (2)'!K9 -> 102 | L6: ='Rangliste (2)'!L9 -> 96 | M6: ='Rangliste (2)'!M9 -> 6 | N6: ='Rangliste (2)'!O9 -> 33 | O6: ='Rangliste (2)'!P9 -> 1.65 | P6: ='Rangliste (2)'!Q9 -> 3.1954545
B7: 5 | D7: Niki | E7: 6 | F7: ='Rangliste (2)'!F22 -> 14 | G7: ='Rangliste (2)'!G22 -> 2 | H7: ='Rangliste (2)'!H22 -> 7 | I7: ='Rangliste (2)'!I22 -> 44 | K7: ='Rangliste (2)'!K22 -> 65 | L7: ='Rangliste (2)'!L22 -> 64 | M7: ='Rangliste (2)'!M22 -> 1 | N7: ='Rangliste (2)'!O22 -> 23 | O7: ='Rangliste (2)'!P22 -> 1.15 | P7: ='Rangliste (2)'!Q22 -> 3.0630435
B8: 6 | D8: Gerald | E8: 13 | F8: ='Rangliste (2)'!F8 -> 13 | G8: ='Rangliste (2)'!G8 -> 3 | H8: ='Rangliste (2)'!H8 -> 15 | I8: ='Rangliste (2)'!I8 -> 42 | K8: ='Rangliste (2)'!K8 -> 76 | L8: ='Rangliste (2)'!L8 -> 94 | M8: ='Rangliste (2)'!M8 -> -18 | N8: ='Rangliste (2)'!O8 -> 31 | O8: ='Rangliste (2)'!P8 -> 1.55 | P8: ='Rangliste (2)'!Q8 -> 2.9048387
B9: 7 | D9: Lukas | E9: 16 | F9: ='Rangliste (2)'!F14 -> 13 | G9: ='Rangliste (2)'!G14 -> 3 | H9: ='Rangliste (2)'!H14 -> 13 | I9: ='Rangliste (2)'!I14 -> 42 | K9: ='Rangliste (2)'!K14 -> 72 | L9: ='Rangliste (2)'!L14 -> 72 | M9: ='Rangliste (2)'!M14 -> 0 | N9: ='Rangliste (2)'!O14 -> 29 | O9: ='Rangliste (2)'!P14 -> 1.45 | P9: ='Rangliste (2)'!Q14 -> 2.8982759
B10: 8 | D10: Alex | E10: 10 | F10: ='Rangliste (2)'!F5 -> 13 | G10: ='Rangliste (2)'!G5 -> 2 | H10: ='Rangliste (2)'!H5 -> 16 | I10: ='Rangliste (2)'!I5 -> 41 | K10: ='Rangliste (2)'!K5 -> 83 | L10: ='Rangliste (2)'!L5 -> 88 | M10: ='Rangliste (2)'!M5 -> -5 | N10: ='Rangliste (2)'!O5 -> 31 | O10: ='Rangliste (2)'!P5 -> 1.55 | P10: ='Rangliste (2)'!Q5 -> 2.8725806
B11: 9 | D11: Andi K. | E11: 16 | F11: ='Rangliste (2)'!F4 -> 13 | G11: ='Rangliste (2)'!G4 -> 2 | H11: ='Rangliste (2)'!H4 -> 15 | I11: ='Rangliste (2)'!I4 -> 41 | K11: ='Rangliste (2)'!K4 -> 76 | L11: ='Rangliste (2)'!L4 -> 82 | M11: ='Rangliste (2)'!M4 -> -6 | N11: ='Rangliste (2)'!O4 -> 30 | O11: ='Rangliste (2)'!P4 -> 1.5 | P11: ='Rangliste (2)'!Q4 -> 2.8666667
B12: 10 | D12: Berni | E12: 3 | F12: ='Rangliste (2)'!F6 -> 11 | G12: ='Rangliste (2)'!G6 -> 1 | H12: ='Rangliste (2)'!H6 -> 9 | I12: ='Rangliste (2)'!I6 -> 34 | K12: ='Rangliste (2)'!K6 -> 60 | L12: ='Rangliste (2)'!L6 -> 66 | M12: ='Rangliste (2)'!M6 -> -6 | N12: ='Rangliste (2)'!O6 -> 21 | O12: ='Rangliste (2)'!P6 -> 1.05 | P12: ='Rangliste (2)'!Q6 -> 2.6690476
B13: 11 | D13: Thomas | E13: 4 | F13: ='Rangliste (2)'!F17 -> 10 | G13: ='Rangliste (2)'!G17 -> 2 | H13: ='Rangliste (2)'!H17 -> 10 | I13: ='Rangliste (2)'!I17 -> 32 | K13: ='Rangliste (2)'!K17 -> 56 | L13: ='Rangliste (2)'!L17 -> 61 | M13: ='Rangliste (2)'!M17 -> -5 | N13: ='Rangliste (2)'!O17 -> 22 | O13: ='Rangliste (2)'!P17 -> 1.1 | P13: ='Rangliste (2)'!Q17 -> 2.5545455
B14: 12 | D14: Mario | E14: 6 | F14: ='Rangliste (2)'!F21 -> 10 | G14: ='Rangliste (2)'!G21 -> 2 | H14: ='Rangliste (2)'!H21 -> 13 | I14: ='Rangliste (2)'!I21 -> 32 | K14: ='Rangliste (2)'!K21 -> 44 | L14: ='Rangliste (2)'!L21 -> 36 | M14: ='Rangliste (2)'!M21 -> 8 | N14: ='Rangliste (2)'!O21 -> 25 | O14: ='Rangliste (2)'!P21 -> 1.25 | P14: ='Rangliste (2)'!Q21 -> 2.53
B15: 14 | D15: Martin | E15: 1 | F15: ='Rangliste (2)'!F15 -> 8 | G15: ='Rangliste (2)'!G15 -> 3 | H15: ='Rangliste (2)'!H15 -> 5 | I15: ='Rangliste (2)'!I15 -> 27 | K15: ='Rangliste (2)'!K15 -> 44 | L15: ='Rangliste (2)'!L15 -> 36 | M15: ='Rangliste (2)'!M15 -> 8 | N15: ='Rangliste (2)'!O15 -> 16 | O15: ='Rangliste (2)'!P15 -> 0.8 | P15: ='Rangliste (2)'!Q15 -> 2.4875
B16: 13 | D16: Harry S. | E16: 1 | F16: ='Rangliste (2)'!F12 -> 8 | G16: ='Rangliste (2)'!G12 -> 0 | H16: ='Rangliste (2)'!H12 -> 13 | I16: ='Rangliste (2)'!I12 -> 24 | K16: ='Rangliste (2)'!K12 -> 49 | L16: ='Rangliste (2)'!L12 -> 59 | M16: ='Rangliste (2)'!M12 -> -10 | N16: ='Rangliste (2)'!O12 -> 21 | O16: ='Rangliste (2)'!P12 -> 1.05 | P16: ='Rangliste (2)'!Q12 -> 2.1928571
B17: 15 | D17: Walter | E17: 0 | F17: ='Rangliste (2)'!F20 -> 5 | G17: ='Rangliste (2)'!G20 -> 2 | H17: ='Rangliste (2)'!H20 -> 6 | I17: ='Rangliste (2)'!I20 -> 17 | K17: ='Rangliste (2)'!K20 -> 33 | L17: ='Rangliste (2)'!L20 -> 30 | M17: ='Rangliste (2)'!M20 -> 3 | N17: ='Rangliste (2)'!O20 -> 13 | O17: ='Rangliste (2)'!P20 -> 0.65 | P17: ='Rangliste (2)'!Q20 -> 1.9576923
B18: 16 | D18: Harry H. | E18: 0 | F18: ='Rangliste (2)'!F11 -> 0 | G18: ='Rangliste (2)'!G11 -> 0 | H18: ='Rangliste (2)'!H11 -> 0 | I18: ='Rangliste (2)'!I11 -> 0 | K18: ='Rangliste (2)'!K11 -> 0 | L18: ='Rangliste (2)'!L11 -> 0 | M18: ='Rangliste (2)'!M11 -> 0 | N18: ='Rangliste (2)'!O11 -> 0 | O18: ='Rangliste (2)'!P11 -> 0 | P18: ='Rangliste (2)'!Q11 -> #DIV/0!
B19: 17 | D19: Tommy | E19: 0 | F19: ='Rangliste (2)'!F18 -> 0 | G19: ='Rangliste (2)'!G18 -> 0 | H19: ='Rangliste (2)'!H18 -> 0 | I19: ='Rangliste (2)'!I18 -> 0 | K19: ='Rangliste (2)'!K18 -> 0 | L19: ='Rangliste (2)'!L18 -> 0 | M19: ='Rangliste (2)'!M18 -> 0 | N19: ='Rangliste (2)'!O18 -> 0 | O19: ='Rangliste (2)'!P18 -> 0 | P19: ='Rangliste (2)'!Q18 -> #DIV/0!
B20: 18 | D20: Roman | E20: 0 | F20: ='Rangliste (2)'!F16 -> 0 | G20: ='Rangliste (2)'!G16 -> 0 | H20: ='Rangliste (2)'!H16 -> 0 | I20: ='Rangliste (2)'!I16 -> 0 | K20: ='Rangliste (2)'!K16 -> 0 | L20: ='Rangliste (2)'!L16 -> 0 | M20: ='Rangliste (2)'!M16 -> 0 | N20: ='Rangliste (2)'!O16 -> 0 | O20: ='Rangliste (2)'!P16 -> 0 | P20: ='Rangliste (2)'!Q16 -> #DIV/0!
B21: 19 | D21: Andi | E21: 0 | F21: ='Rangliste (2)'!F3 -> 0 | G21: ='Rangliste (2)'!G3 -> 0 | H21: ='Rangliste (2)'!H3 -> 0 | I21: ='Rangliste (2)'!I3 -> 0 | K21: ='Rangliste (2)'!K3 -> 0 | L21: ='Rangliste (2)'!L3 -> 0 | M21: ='Rangliste (2)'!M3 -> 0 | N21: ='Rangliste (2)'!O3 -> 0 | O21: ='Rangliste (2)'!P3 -> 0 | P21: ='Rangliste (2)'!Q3 -> #DIV/0!
B22: 20 | D22: Gerhard L. | E22: 0 | F22: ='Rangliste (2)'!F10 -> 0 | G22: ='Rangliste (2)'!G10 -> 0 | H22: ='Rangliste (2)'!H10 -> 0 | I22: ='Rangliste (2)'!I10 -> 0 | K22: ='Rangliste (2)'!K10 -> 0 | L22: ='Rangliste (2)'!L10 -> 0 | M22: ='Rangliste (2)'!M10 -> 0 | N22: ='Rangliste (2)'!O10 -> 0 | O22: ='Rangliste (2)'!P10 -> 0 | P22: ='Rangliste (2)'!Q10 -> #DIV/0!

Sheet Rangliste (2)
B2: Rg | D2: Name | E2: SpU | F2: S | G2: U | H2: N | I2: Pkt | K2: Tore | L2: Gegentore | M2: Tordiff. | O2: Sp | P2: A | Q2: Pkt/Sp+A
B3: 1 | D3: Andi | F3: =Spiele!AW6 -> 0 | G3: =Spiele!AX6 -> 0 | H3: =Spiele!AY6 -> 0 | I3: =F3*3+G3 -> 0 | K3: =Teamtore!AR6 -> 0 | L3: =Gegentore!AR6 -> 0 | M3: =K3-L3 -> 0 | O3: =Spiele!AS6 -> 0 | P3: =O3*0.05 -> 0 | Q3: =(I3/O3)+P3 -> #DIV/0!
B4: 2 | D4: Andi K. | F4: =Spiele!AW7 -> 13 | G4: =Spiele!AX7 -> 2 | H4: =Spiele!AY7 -> 15 | I4: =F4*3+G4 -> 41 | K4: =Teamtore!AR7 -> 76 | L4: =Gegentore!AR7 -> 82 | M4: =K4-L4 -> -6 | O4: =Spiele!AS7 -> 30 | P4: =O4*0.05 -> 1.5 | Q4: =(I4/O4)+P4 -> 2.8666667
B5: 3 | D5: Alex | F5: =Spiele!AW24 -> 13 | G5: =Spiele!AX24 -> 2 | H5: =Spiele!AY24 -> 16 | I5: =F5*3+G5 -> 41 | K5: =Teamtore!AR8 -> 83 | L5: =Gegentore!AR8 -> 88 | M5: =K5-L5 -> -5 | O5: =Spiele!AS24 -> 31 | P5: =O5*0.05 -> 1.55 | Q5: =(I5/O5)+P5 -> 2.8725806
B6: 4 | D6: Berni | F6: =Spiele!AW9 -> 11 | G6: =Spiele!AX9 -> 1 | H6: =Spiele!AY9 -> 9 | I6: =F6*3+G6 -> 34 | K6: =Teamtore!AR9 -> 60 | L6: =Gegentore!AR9 -> 66 | M6: =K6-L6 -> -6 | O6: =Spiele!AS9 -> 21 | P6: =O6*0.05 -> 1.05 | Q6: =(I6/O6)+P6 -> 2.6690476
B7: 5 | D7: Franz | F7: =Spiele!AW10 -> 16 | G7: =Spiele!AX10 -> 3 | H7: =Spiele!AY10 -> 17 | I7: =F7*3+G7 -> 51 | K7: =Teamtore!AR10 -> 98 | L7: =Gegentore!AR10 -> 103 | M7: =K7-L7 -> -5 | O7: =Spiele!AS10 -> 36 | P7: =O7*0.05 -> 1.8 | Q7: =(I7/O7)+P7 -> 3.2166667
B8: 6 | D8: Gerald | F8: =Spiele!AW11 -> 13 | G8: =Spiele!AX11 -> 3 | H8: =Spiele!AY11 -> 15 | I8: =F8*3+G8 -> 42 | K8: =Teamtore!AR11 -> 76 | L8: =Gegentore!AR11 -> 94 | M8: =K8-L8 -> -18 | O8: =Spiele!AS11 -> 31 | P8: =O8*0.05 -> 1.55 | Q8: =(I8/O8)+P8 -> 2.9048387
B9: 7 | D9: Gerhard C. | F9: =Spiele!AW12 -> 16 | G9: =Spiele!AX12 -> 3 | H9: =Spiele!AY12 -> 14 | I9: =F9*3+G9 -> 51 | K9: =Teamtore!AR12 -> 102 | L9: =Gegentore!AR12 -> 96 | M9: =K9-L9 -> 6 | O9: =Spiele!AS12 -> 33 | P9: =O9*0.05 -> 1.65 | Q9: =(I9/O9)+P9 -> 3.1954545
B10: 8 | D10: Gerhard L. | F10: =Spiele!AW13 -> 0 | G10: =Spiele!AX13 -> 0 | H10: =Spiele!AY13 -> 0 | I10: =F10*3+G10 -> 0 | K10: =Teamtore!AR13 -> 0 | L10: =Gegentore!AR13 -> 0 | M10: =K10-L10 -> 0 | O10: =Spiele!AS13 -> 0 | P10: =O10*0.05 -> 0 | Q10: =(I10/O10)+P10 -> #DIV/0!
B11: 9 | D11: Harry H. | F11: =Spiele!AW14 -> 0 | G11: =Spiele!AX14 -> 0 | H11: =Spiele!AY14 -> 0 | I11: =F11*3+G11 -> 0 | K11: =Teamtore!AR14 -> 0 | L11: =Gegentore!AR14 -> 0 | M11: =K11-L11 -> 0 | O11: =Spiele!AS14 -> 0 | P11: =O11*0.05 -> 0 | Q11: =(I11/O11)+P11 -> #DIV/0!
B12: 10 | D12: Harry S. | F12: =Spiele!AW15 -> 8 | G12: =Spiele!AX15 -> 0 | H12: =Spiele!AY15 -> 13 | I12: =F12*3+G12 -> 24 | K12: =Teamtore!AR15 -> 49 | L12: =Gegentore!AR15 -> 59 | M12: =K12-L12 -> -10 | O12: =Spiele!AS15 -> 21 | P12: =O12*0.05 -> 1.05 | Q12: =(I12/O12)+P12 -> 2.1928571
B13: 11 | D13: Harry Sch. | F13: =Spiele!AW16 -> 20 | G13: =Spiele!AX16 -> 2 | H13: =Spiele!AY16 -> 15 | I13: =F13*3+G13 -> 62 | K13: =Teamtore!AR16 -> 117 | L13: =Gegentore!AR16 -> 100 | M13: =K13-L13 -> 17 | O13: =Spiele!AS16 -> 37 | P13: =O13*0.05 -> 1.85 | Q13: =(I13/O13)+P13 -> 3.5256757
B14: 12 | D14: Lukas | F14: =Spiele!AW17 -> 13 | G14: =Spiele!AX17 -> 3 | H14: =Spiele!AY17 -> 13 | I14: =F14*3+G14 -> 42 | K14: =Teamtore!AR17 -> 72 | L14: =Gegentore!AR17 -> 72 | M14: =K14-L14 -> 0 | O14: =Spiele!AS17 -> 29 | P14: =O14*0.05 -> 1.45 | Q14: =(I14/O14)+P14 -> 2.8982759
B15: 13 | D15: Martin | F15: =Spiele!AW23 -> 8 | G15: =Spiele!AX23 -> 3 | H15: =Spiele!AY23 -> 5 | I15: =F15*3+G15 -> 27 | K15: =Teamtore!AR23 -> 44 | L15: =Gegentore!AR23 -> 36 | M15: =K15-L15 -> 8 | O15: =Spiele!AS23 -> 16 | P15: =O15*0.05 -> 0.8 | Q15: =(I15/O15)+P15 -> 2.4875
B16: 14 | D16: Roman | F16: =Spiele!AW18 -> 0 | G16: =Spiele!AX18 -> 0 | H16: =Spiele!AY18 -> 0 | I16: =F16*3+G16 -> 0 | K16: =Teamtore!AR18 -> 0 | L16: =Gegentore!AR18 -> 0 | M16: =K16-L16 -> 0 | O16: =Spiele!AS18 -> 0 | P16: =O16*0.05 -> 0 | Q16: =(I16/O16)+P16 -> #DIV/0!
B17: 15 | D17: Thomas | F17: =Spiele!AW19 -> 10 | G17: =Spiele!AX19 -> 2 | H17: =Spiele!AY19 -> 10 | I17: =F17*3+G17 -> 32 | K17: =Teamtore!AR19 -> 56 | L17: =Gegentore!AR19 -> 61 | M17: =K17-L17 -> -5 | O17: =Spiele!AS19 -> 22 | P17: =O17*0.05 -> 1.1 | Q17: =(I17/O17)+P17 -> 2.5545455
B18: 16 | D18: Tommy | F18: =Spiele!AW20 -> 0 | G18: =Spiele!AX20 -> 0 | H18: =Spiele!AY20 -> 0 | I18: =F18*3+G18 -> 0 | K18: =Teamtore!AR20 -> 0 | L18: =Gegentore!AR20 -> 0 | M18: =K18-L18 -> 0 | O18: =Spiele!AS20 -> 0 | P18: =O18*0.05 -> 0 | Q18: =(I18/O18)+P18 -> #DIV/0!
B19: 17 | D19: Viktor | F19: =Spiele!AW21 -> 18 | G19: =Spiele!AX21 -> 3 | H19: =Spiele!AY21 -> 13 | I19: =F19*3+G19 -> 57 | K19: =Teamtore!AR21 -> 104 | L19: =Gegentore!AR21 -> 95 | M19: =K19-L19 -> 9 | O19: =Spiele!AS21 -> 34 | P19: =O19*0.05 -> 1.7 | Q19: =(I19/O19)+P19 -> 3.3764706
B20: 18 | D20: Walter | F20: =Spiele!AW22 -> 5 | G20: =Spiele!AX22 -> 2 | H20: =Spiele!AY22 -> 6 | I20: =F20*3+G20 -> 17 | K20: =Teamtore!AR22 -> 33 | L20: =Gegentore!AR22 -> 30 | M20: =K20-L20 -> 3 | O20: =Spiele!AS22 -> 13 | P20: =O20*0.05 -> 0.65 | Q20: =(I20/O20)+P20 -> 1.9576923
B21: 19 | D21: Mario | F21: =Spiele!AW25 -> 10 | G21: =Spiele!AX25 -> 2 | H21: =Spiele!AY25 -> 13 | I21: =F21*3+G21 -> 32 | K21: =Teamtore!AR23 -> 44 | L21: =Gegentore!AR23 -> 36 | M21: =K21-L21 -> 8 | O21: =Spiele!AS25 -> 25 | P21: =O21*0.05 -> 1.25 | Q21: =(I21/O21)+P21 -> 2.53
B22: 20 | D22: Niki | F22: =Spiele!AW26 -> 14 | G22: =Spiele!AX24 -> 2 | H22: =Spiele!AY26 -> 7 | I22: =F22*3+G22 -> 44 | K22: =Teamtore!AR24 -> 65 | L22: =Gegentore!AR24 -> 64 | M22: =K22-L22 -> 1 | O22: =Spiele!AS26 -> 23 | P22: =O22*0.05 -> 1.15 | Q22: =(I22/O22)+P22 -> 3.0630435

Sheet Begegnungen
C1: 1 | I1: 2
B2: Datum | D2: Aufstellung | H2: Datum | J2: Aufstellung
B3: =Spiele!D5 -> 45538 | H3: =Spiele!E5 -> 45545
C4: Alex | E4: Berni | I4: Andi K. | K4: Alex
C5: Andi K. | E5: Franz | I5: Franz | K5: Harry Sch.
C6: Gerald | D6: gegen | E6: Harry Sch. | I6: Gerald | J6: gegen | K6: Martin
C7: Gerhard C. | E7: Martin | I7: Lukas | K7: Viktor
C8: Lukas | E8: Viktor | I8: Thomas | K8: Walter
E9: Walter
D11: Resultat | J11: Resultat
C13: 2 | D13: : | E13: 2 | I13: 1 | J13: : | K13: 0
C16: =IF(C13>E13,"3",IF(C13=E13,"1","0")) -> 1 | D16: Punkte | E16: =IF(E13>C13,"3",IF(E13=C13,"1","0")) -> 1 | I16: =IF(I13>K13,"3",IF(I13=K13,"1","0")) -> 3 | J16: Punkte | K16: =IF(K13>I13,"3",IF(K13=I13,"1","0")) -> 0
B18: Datum | D18: Aufstellung | H18: Datum | J18: Aufstellung
B19: =Spiele!F5 -> 45552 | H19: =Spiele!G5 -> 45559
C20: Alex | E20: Andi K. | I20: Franz | K20: Alex
C21: Harry Sch. | E21: Lukas | I21: Harry Sch. | K21: Andi K.
C22: Martin | D22: gegen | E22: Mario | I22: Mario | J22: gegen | K22: Lukas
C23: Viktor | E23: Niki | I23: Martin | K23: Niki
C24: Walter | I24: Viktor
D27: Resultat | J27: Resultat
C29: 6 | D29: : | E29: 4 | I29: 3 | J29: : | K29: 2
C32: =IF(C29>E29,"3",IF(C29=E29,"1","0")) -> 3 | D32: Punkte | E32: =IF(E29>C29,"3",IF(E29=C29,"1","0")) -> 0 | I32: =IF(I29>K29,"3",IF(I29=K29,"1","0")) -> 3 | J32: Punkte | K32: =IF(K29>I29,"3",IF(K29=I29,"1","0")) -> 0
B34: Datum | D34: Aufstellung | H34: Datum | J34: Aufstellung
B35: =Spiele!H5 -> 45566 | H35: =Spiele!I5 -> 45573
C36: Gerhard C. | E36: Alex | I36: Franz | K36: Gerald
C37: Harry Sch. | E37: Andi K. | I37: Harry Sch. | K37: Gerhard C.
C38: Mario | D38: gegen | E38: Franz | I38: Mario | J38: gegen | K38: Lukas
C39: Niki | E39: Gerald | I39: Martin | K39: Niki
C40: Viktor | E40: Thomas | I40: Viktor | K40: Thomas
D44: Resultat | J44: Resultat
C46: 6 | D46: : | E46: 1 | I46: 3 | J46: : | K46: 3
C49: =IF(C46>E46,"3",IF(C46=E46,"1","0")) -> 3 | D49: Punkte | E49: =IF(E46>C46,"3",IF(E46=C46,"1","0")) -> 0 | I49: =IF(I46>K46,"3",IF(I46=K46,"1","0")) -> 1 | J49: Punkte | K49: =IF(K46>I46,"3",IF(K46=I46,"1","0")) -> 1
B51: Datum | D51: Aufstellung | H51: Datum | J51: Aufstellung
B52: =Spiele!J5 -> 45580 | C52: Alex | E52: Franz | H52: =Spiele!K5 -> 45587
C53: Andi K. | E53: Gerhard C. | I53: Franz | K53: Alex
C54: Gerald | E54: Harry S. | I54: Gerhard C. | K54: Gerald
C55: Harry Sch. | D55: gegen | E55: Mario | I55: Harry Sch. | J55: gegen | K55: Harry S.
C56: Lukas | E56: Martin | I56: Martin | K56: Niki
C57: Thomas | E57: Viktor | I57: Viktor | K57: Thomas
E58: Walter
...

Sheet Tore
E4: 1 | F4: 2 | G4: 3 | H4: 4 | I4: 5 | J4: 6 | K4: 7 | L4: 8 | M4: 9 | N4: 10 | O4: 11 | P4: 12 | Q4: 13 | R4: 14 | S4: 15 | T4: 16 | U4: 17 | V4: 18 | W4: 19 | X4: 20 | Y4: 21 | Z4: 22 | AA4: 23 | AB4: 24 | AC4: 25 | AD4: 26 | AE4: 27 | AF4: 28 | AG4: 29 | AH4: 30 | AI4: 31 | AJ4: 32 | AK4: 33 | AL4: 34 | AM4: 35 | AN4: 36 | AO4: 37 | AP4: 38 | AQ4: 39 | AR4: 40 | AS4: 41
B5: Rg | E5: =Spiele!D5 -> 45538 | F5: =Spiele!E5 -> 45545 | G5: =Spiele!F5 -> 45552 | H5: =Spiele!G5 -> 45559 | I5: =Spiele!H5 -> 45566 | J5: =Spiele!I5 -> 45573 | K5: =Spiele!J5 -> 45580 | L5: =Spiele!K5 -> 45587 | ... AR5: =Spiele!AQ5 -> 45832 | AT5: Tore | AU5: ET
B6: 1 | D6: Alex | E6: 1 | F6: ='Tore (2)'!F21 -> 0 | G6: 4 | H6: ='Tore (2)'!H21 -> 0 | I6: 0 | J6: ='Tore (2)'!J21 -> 0 | K6: ='Tore (2)'!K21 -> 0 | L6: ='Tore (2)'!L21 -> 0 | M6: ='Tore (2)'!M21 -> 0 | N6: ='Tore (2)'!N21 -> 0 | O6: 1 | P6: ='Tore (2)'!P21 -> 0 | Q6: 2 | R6: 2 | S6: 2 | T6: 2 | U6: 1 | V6: 2 | W6: ='Tore (2)'!W21 -> 0 | X6: 3 | Y6: 4 | Z6: ='Tore (2)'!Z21 -> 0 | AA6: ='Tore (2)'!AA21 -> 0 | AB6: ='Tore (2)'!AB21 -> 0 | AC6: 0 | AD6: 1 | AE6: 1 | AF6: 1 | AG6: 2 | AH6: ='Tore (2)'!AH21 -> 0 | AI6: 0 | AJ6: ='Tore (2)'!AJ21 -> 0 | AK6: ='Tore (2)'!AK21 -> 0 | AL6: 1 | AM6: 2 | AN6: ='Tore (2)'!AN21 -> 0 | AO6: ='Tore (2)'!AO21 -> 0 | AP6: ='Tore (2)'!AP21 -> 0 | AQ6: 1 | AR6: ='Tore (2)'!AR21 -> 0 | AS6: ='Tore (2)'!AS21 -> 0 | AT6: =SUM(E6:AR6) -> 33
B7: 2 | D7: Gerhard C. | E7: 1 | F7: 0 | G7: 0 | H7: ='Tore (2)'!H12 -> 0 | I7: 2 | J7: 1 | K7: 1 | L7: 1 | M7: 1 | N7: ='Tore (2)'!N12 -> 0 | O7: 1 | P7: 1 | Q7: 0 | R7: 1 | S7: 0 | T7: ='Tore (2)'!T12 -> 0 | U7: 2 | V7: ='Tore (2)'!V12 -> 0 | W7: ='Tore (2)'!W12 -> 0 | X7: 0 | Y7: 1 | Z7: 0 | AA7: 4 | AB7: 3 | AC7: 1 | AD7: 1 | AE7: 0 | AF7: 2 | AG7: 0 | AH7: ='Tore (2)'!AH12 -> 0 | AI7: ='Tore (2)'!AI12 -> 0 | AJ7: ='Tore (2)'!AJ12 -> 0 | AK7: 1 | AL7: 0 | AM7: 2 | AN7: 1 | AO7: ='Tore (2)'!AO12 -> 0 | AP7: 1 | AQ7: 1 | AR7: ='Tore (2)'!AR12 -> 0 | AS7: ='Tore (2)'!AS12 -> 0 | AT7: =SUM(E7:AR7) -> 30
B8: 3 | D8: Franz | E8: 0 | F8: 0 | G8: ='Tore (2)'!G10 -> 0 | H8: 0 | I8: 1 | J8: 0 | K8: 0 | L8: 1 | M8: 0 | N8: 0 | O8: 1 | P8: ='Tore (2)'!P10 -> 0 | Q8: 0 | R8: 0 | S8: 0 | T8: 2 | U8: 0 | V8: 0 | W8: 2 | X8: 2 | Y8: 1 | Z8: 1 | AA8: 1 | AB8: 2 | AC8: 1 | AD8: 1 | AE8: ='Tore (2)'!AE10 -> 0 | AF8: 2 | AG8: 0 | AH8: 0 | AI8: 1 | AJ8: ='Tore (2)'!AJ10 -> 0 | AK8: ='Tore (2)'!AK10 -> 0 | AL8: ='Tore (2)'!AL10 -> 0 | AM8: ='Tore (2)'!AM10 -> 0 | AN8: ='Tore (2)'!AN10 -> 0 | AO8: 2 | AP8: ='Tore (2)'!AP10 -> 0 | AQ8: ='Tore (2)'!AQ10 -> 0 | AR8: 1 | AS8: ='Tore (2)'!AS10 -> 0 | AT8: =SUM(E8:AR8) -> 22
B9: 4 | D9: Harry Sch. | E9: 0 | F9: ='Tore (2)'!F16 -> 0 | G9: 0 | H9: 1 | I9: 2 | J9: 2 | K9: ='Tore (2)'!K16 -> 0 | L9: 1 | M9: 0 | N9: 0 | O9: ='Tore (2)'!O16 -> 0 | P9: 0 | Q9: 0 | R9: ='Tore (2)'!R16 -> 0 | S9: 0 | T9: 1 | U9: 0 | V9: 0 | W9: 0 | X9: 4 | Y9: 1 | Z9: 0 | AA9: 0 | AB9: 2 | AC9: 0 | AD9: 0 | AE9: 3 | AF9: ='Tore (2)'!AF16 -> 0 | AG9: 0 | AH9: 0 | AI9: ='Tore (2)'!AI16 -> 0 | AJ9: ='Tore (2)'!AJ16 -> 0 | AK9: 1 | AL9: ='Tore (2)'!AL16 -> 0 | AM9: 2 | AN9: ='Tore (2)'!AN16 -> 0 | AO9: ='Tore (2)'!AO16 -> 0 | AP9: ='Tore (2)'!AP16 -> 0 | AQ9: ='Tore (2)'!AQ16 -> 0 | AR9: 2 | AS9: ='Tore (2)'!AS16 -> 0 | AT9: =SUM(E9:AR9) -> 22 | AU9: 1
B10: 5 | D10: Andi K. | E10: 0 | F10: ='Tore (2)'!F7 -> 0 | G10: 0 | H10: 1 | I10: 0 | J10: 0 | K10: 0 | L10: 0 | M10: 1 | N10: 1 | O10: 0 | P10: 0 | Q10: 0 | R10: 0 | S10: 0 | T10: 0 | U10: 2 | V10: 1 | W10: 1 | X10: 0 | Y10: 0 | Z10: 1 | AA10: 0 | AB10: ='Tore (2)'!AB7 -> 0 | AC10: 0 | AD10: 2 | AE10: 0 | AF10: 0 | AG10: ='Tore (2)'!AG7 -> 0 | AH10: 3 | AI10: 1 | AJ10: 2 | AK10: ='Tore (2)'!AK7 -> 0 | AL10: 0 | AM10: ='Tore (2)'!AM7 -> 0 | AN10: 2 | AO10: ='Tore (2)'!AO7 -> 0 | AP10: ='Tore (2)'!AP7 -> 0 | AQ10: 2 | AR10: ='Tore (2)'!AR7 -> 0 | AS10: ='Tore (2)'!AS7 -> 0 | AT10: =SUM(E10:AR10) -> 20 | AU10: 1
B11: 6 | D11: Mario | E11: ='Tore (2)'!E23 -> 0 | F11: ='Tore (2)'!F23 -> 0 | G11: 2 | H11: 1 | I11: 2 | J11: 1 | K11: ='Tore (2)'!K23 -> 0 | L11: ='Tore (2)'!L23 -> 0 | M11: 2 | N11: ='Tore (2)'!N23 -> 0 | O11: ='Tore (2)'!O23 -> 0 | P11: 1 | Q11: 2 | R11: ='Tore (2)'!R23 -> 0 | S11: ='Tore (2)'!S23 -> 0 | T11: ='Tore (2)'!T23 -> 0 | U11: ='Tore (2)'!U23 -> 0 | V11: 0 | W11: ='Tore (2)'!W23 -> 0 | X11: ='Tore (2)'!X23 -> 0 | Y11: ='Tore (2)'!Y23 -> 0 | Z11: ='Tore (2)'!Z23 -> 0 | AA11: ='Tore (2)'!AA23 -> 0 | AB11: ='Tore (2)'!AB23 -> 0 | AC11: ='Tore (2)'!AC23 -> 0 | AD11: ='Tore (2)'!AD23 -> 0 | AE11: 1 | AF11: 1 | AG11: 0 | AH11: ='Tore (2)'!AH23 -> 0 | AI11: ='Tore (2)'!AI23 -> 0 | AJ11: 1 | AK11: ='Tore (2)'!AK23 -> 0 | AL11: 1 | AM11: 1 | AN11: ='Tore (2)'!AN23 -> 0 | AO11: ='Tore (2)'!AO23 -> 0 | AP11: ='Tore (2)'!AP23 -> 0 | AQ11: 2 | AR11: ='Tore (2)'!AR23 -> 0 | AS11: ='Tore (2)'!AS23 -> 0 | AT11: =SUM(E11:AR11) -> 18 | AU11: 1
B12: 7 | D12: Niki | E12: ='Tore (2)'!E13 -> 0 | F12: ='Tore (2)'!F13 -> 0 | G12: 1 | H12: ='Tore (2)'!H13 -> 0 | I12: ='Tore (2)'!I13 -> 0 | J12: 1 | K12: ='Tore (2)'!K13 -> 0 | L12: ='Tore (2)'!L13 -> 0 | M12: ='Tore (2)'!M13 -> 0 | N12: ='Tore (2)'!N13 -> 0 | O12: ='Tore (2)'!O13 -> 0 | P12: 1 | Q12: ='Tore (2)'!Q13 -> 0 | R12: ='Tore (2)'!R13 -> 0 | S12: ='Tore (2)'!S13 -> 0 | T12: ='Tore (2)'!T13 -> 0 | U12: 1 | V12: ='Tore (2)'!V13 -> 0 | W12: ='Tore (2)'!W13 -> 0 | X12: 3 | Y12: ='Tore (2)'!Y13 -> 0 | Z12: ='Tore (2)'!Z13 -> 0 | AA12: 3 | AB12: 1 | AC12: ='Tore (2)'!AC13 -> 0 | AD12: ='Tore (2)'!AD13 -> 0 | AE12: 0 | AF12: ='Tore (2)'!AF13 -> 0 | AG12: 2 | AH12: 1 | AI12: ='Tore (2)'!AI13 -> 0 | AJ12: ='Tore (2)'!AJ13 -> 0 | AK12: 3 | AL12: ='Tore (2)'!AL13 -> 0 | AM12: ='Tore (2)'!AM13 -> 0 | AN12: ='Tore (2)'!AN13 -> 0 | AO12: ='Tore (2)'!AO13 -> 0 | AP12: ='Tore (2)'!AP13 -> 0 | AQ12: ='Tore (2)'!AQ13 -> 0 | AR12: ='Tore (2)'!AR13 -> 0 | AS12: ='Tore (2)'!AS13 -> 0 | AT12: =SUM(E12:AR12) -> 17
B13: 8 | D13: Martin | E13: 1 | F13: 0 | G13: 2 | H13: 1 | I13: ='Tore (2)'!I18 -> 0 | J13: ='Tore (2)'!J18 -> 0 | K13: 1 | L13: 1 | M13: 0 | N13: 0 | O13: 0 | P13: 0 | Q13: 0 | R13: 0 | S13: 0 | T13: 0 | U13: 0 | V13: 0 | W13: 0 | X13: 0 | Y13: 1 | Z13: 0 | AA13: 0 | AB13: 0 | AC13: 0 | AD13: 0 | AE13: 0 | AF13: 0 | AG13: 0 | AH13: 0 | AI13: 0 | AJ13: 0 | AK13: 2 | AL13: 0 | AM13: 1 | AN13: 2 | AO13: 1 | AP13: 2 | AQ13: ='Tore (2)'!AQ18 -> 0 | AR13: 1 | AS13: ='Tore (2)'!AS18 -> 0 | AT13: =SUM(E13:AR13) -> 16
B14: 9 | D14: Berni | E14: 1 | F14: 0 | G14: 0 | H14: 0 | I14: 0 | J14: 0 | K14: 0 | L14: ='Tore (2)'!L9 -> 0 | M14: 0 | N14: ='Tore (2)'!N9 -> 0 | O14: 0 | P14: ='Tore (2)'!P9 -> 0 | Q14: ='Tore (2)'!Q9 -> 0 | R14: 0 | S14: 1 | T14: ='Tore (2)'!T9 -> 0 | U14: 2 | V14: ='Tore (2)'!V9 -> 0 | W14: ='Tore (2)'!W9 -> 0 | X14: ='Tore (2)'!X9 -> 0 | Y14: 0 | Z14: ='Tore (2)'!Z9 -> 0 | AA14: 2 | AB14: 0 | AC14: 2 | AD14: ='Tore (2)'!AD9 -> 0 | AE14: 2 | AF14: 1 | AG14: 0 | AH14: 0 | AI14: 3 | AJ14: ='Tore (2)'!AJ9 -> 0 | AK14: ='Tore (2)'!AK9 -> 0 | AL14: 0 | AM14: ='Tore (2)'!AM9 -> 0 | AN14: ='Tore (2)'!AN9 -> 0 | AO14: ='Tore (2)'!AO9 -> 0 | AP14: ='Tore (2)'!AP9 -> 0 | AQ14: 1 | AR14: 1 | AS14: ='Tore (2)'!AS9 -> 0 | AT14: =SUM(E14:AR14) -> 16
B15: 10 | D15: Lukas | E15: 0 | F15: 0 | G15: 1 | H15: 1 | I15: 0 | J15: 0 | K15: 0 | L15: 0 | M15: 1 | N15: 0 | O15: 0 | P15: 0 | Q15: ='Tore (2)'!Q17 -> 0 | R15: 0 | S15: 1 | T15: 1 | U15: 0 | V15: ='Tore (2)'!V17 -> 0 | W15: 1 | X15: ='Tore (2)'!X17 -> 0 | Y15: 0 | Z15: 2 | AA15: 0 | AB15: 1 | AC15: 0 | AD15: 1 | AE15: 0 | AF15: 0 | AG15: ='Tore (2)'!AG17 -> 0 | AH15: 2 | AI15: ='Tore (2)'!AI17 -> 0 | AJ15: 0 | AK15: 1 | AL15: ='Tore (2)'!AL17 -> 0 | AM15: ='Tore (2)'!AM17 -> 0 | AN15: ='Tore (2)'!AN17 -> 0 | AO15: ='Tore (2)'!AO17 -> 0 | AP15: ='Tore (2)'!AP17 -> 0 | AQ15: ='Tore (2)'!AQ17 -> 0 | AR15: ='Tore (2)'!AR17 -> 0 | AS15: ='Tore (2)'!AS17 -> 0 | AT15: =SUM(E15:AR15) -> 13 | AU15: 1
B16: 11 | D16: Thomas | E16: ='Tore (2)'!E20 -> 0 | F16: 1 | G16: ='Tore (2)'!G20 -> 0 | H16: 0 | I16: 0 | J16: 1 | K16: 2 | L16: 1 | M16: 0 | N16: 0 | O16: 1 | P16: ='Tore (2)'!P20 -> 0 | Q16: 1 | R16: 0 | S16: 0 | T16: 1 | U16: 0 | V16: 0 | W16: 0 | X16: 0 | Y16: 1 | Z16: ='Tore (2)'!Z20 -> 0 | AA16: 0 | AB16: ='Tore (2)'!AB20 -> 0 | AC16: ='Tore (2)'!AC20 -> 0 | AD16: 1 | AE16: 0 | AF16: 0 | AG16: 0 | AH16: ='Tore (2)'!AH20 -> 0 | AI16: ='Tore (2)'!AI20 -> 0 | AJ16: ='Tore (2)'!AJ20 -> 0 | AK16: ='Tore (2)'!AK20 -> 0 | AL16: ='Tore (2)'!AL20 -> 0 | AM16: ='Tore (2)'!AM20 -> 0 | AN16: ='Tore (2)'!AN20 -> 0 | AO16: ='Tore (2)'!AO20 -> 0 | AP16: ='Tore (2)'!AP20 -> 0 | AQ16: 2 | AR16: ='Tore (2)'!AR20 -> 0 | AS16: ='Tore (2)'!AS20 -> 0 | AT16: =SUM(E16:AR16) -> 12
B17: 12 | D17: Gerald | E17: ='Tore (2)'!E11 -> 0 | F17: ='Tore (2)'!F11 -> 0 | G17: ='Tore (2)'!G11 -> 0 | H17: ='Tore (2)'!H11 -> 0 | I17: ='Tore (2)'!I11 -> 0 | J17: 0 | K17: 1 | L17: ='Tore (2)'!L11 -> 0 | M17: 1 | N17: ='Tore (2)'!N11 -> 0 | O17: ='Tore (2)'!O11 -> 0 | P17: ='Tore (2)'!P11 -> 0 | Q17: ='Tore (2)'!Q11 -> 0 | R17: ='Tore (2)'!R11 -> 0 | S17: ='Tore (2)'!S11 -> 0 | T17: ='Tore (2)'!T11 -> 0 | U17: ='Tore (2)'!U11 -> 0 | ... AA17: ='Tore (2)'!AA11 -> 0 | AB17: 1 | AC17: ='Tore (2)'!AC11 -> 0 | AD17: ='Tore (2)'!AD11 -> 0 | AE17: 0 | AF17: 1 | AG17: 0 | AH17: ='Tore (2)'!AH11 -> 0 | AI17: ='Tore (2)'!AI11 -> 0 | AJ17: ='Tore (2)'!AJ11 -> 0 | AK17: ='Tore (2)'!AK11 -> 0 | AL17: ='Tore (2)'!AL11 -> 0 | AM17: ='Tore (2)'!AM11 -> 0 | AN17: ='Tore (2)'!AN11 -> 0 | AO17: ='Tore (2)'!AO11 -> 0 | ... AS17: ='Tore (2)'!AS11 -> 0 | AT17: =SUM(E17:AR17) -> 4 | AU17: 1
B18: 13 | D18: Harry S. | E18: ='Tore (2)'!E15 -> 0 | F18: 0 | G18: ='Tore (2)'!G15 -> 0 | H18: ='Tore (2)'!H15 -> 0 | I18: ='Tore (2)'!I15 -> 0 | J18: ='Tore (2)'!J15 -> 0 | K18: 0 | L18: ='Tore (2)'!L15 -> 0 | M18: ='Tore (2)'!M15 -> 0 | N18: 0 | O18: ='Tore (2)'!O15 -> 0 | P18: ='Tore (2)'!P15 -> 0 | Q18: ='Tore (2)'!Q15 -> 0 | R18: ='Tore (2)'!R15 -> 0 | S18: 0 | T18: ='Tore (2)'!T15 -> 0 | U18: ='Tore (2)'!U15 -> 0 | V18: 0 | W18: ='Tore (2)'!W15 -> 0 | X18: ='Tore (2)'!X15 -> 0 | Y18: 1 | Z18: ='Tore (2)'!Z15 -> 0 | AA18: 0 | AB18: 0 | AC18: ='Tore (2)'!AC15 -> 0 | AD18: ='Tore (2)'!AD15 -> 0 | AE18: 0 | AF18: 0 | AG18: ='Tore (2)'!AG15 -> 0 | AH18: 0 | AI18: ='Tore (2)'!AI15 -> 0 | AJ18: ='Tore (2)'!AJ15 -> 0 | AK18: ='Tore (2)'!AK15 -> 0 | AL18: 0 | AM18: ='Tore (2)'!AM15 -> 0 | AN18: ='Tore (2)'!AN15 -> 0 | AO18: ='Tore (2)'!AO15 -> 0 | AP18: ='Tore (2)'!AP15 -> 0 | AQ18: ='Tore (2)'!AQ15 -> 0 | AR18: ='Tore (2)'!AR15 -> 0 | AS18: ='Tore (2)'!AS15 -> 0 | AT18: =SUM(E18:AR18) -> 1
B19: 14 | D19: Christoph | E19: ='Tore (2)'!E6 -> 0 | F19: ='Tore (2)'!F6 -> 0 | G19: ='Tore (2)'!G6 -> 0 | H19: ='Tore (2)'!H6 -> 0 | I19: ='Tore (2)'!I6 -> 0 | J19: ='Tore (2)'!J6 -> 0 | K19: ='Tore (2)'!K6 -> 0 | L19: ='Tore (2)'!L6 -> 0 | ... T19: ='Tore (2)'!T6 -> 0 | U19: 0 | V19: ='Tore (2)'!V6 -> 0 | W19: ='Tore (2)'!W6 -> 0 | X19: ='Tore (2)'!X6 -> 0 | Y19: ='Tore (2)'!Y6 -> 0 | Z19: ='Tore (2)'!Z6 -> 0 | AA19: ='Tore (2)'!AA6 -> 0 | AB19: ='Tore (2)'!AB6 -> 0 | AC19: ='Tore (2)'!AC6 -> 0 | AD19: ='Tore (2)'!AD6 -> 0 | AE19: 0 | AF19: ='Tore (2)'!AF6 -> 0 | AG19: 0 | AH19: ='Tore (2)'!AH6 -> 0 | AI19: ='Tore (2)'!AI6 -> 0 | AJ19: 0 | AK19: 0 | AL19: 0 | AM19: ='Tore (2)'!AM6 -> 0 | AN19: ='Tore (2)'!AN6 -> 0 | AO19: ='Tore (2)'!AO6 -> 0 | AP19: ='Tore (2)'!AP6 -> 0 | AQ19: ='Tore (2)'!AQ6 -> 0 | AR19: ='Tore (2)'!AR6 -> 0 | AS19: ='Tore (2)'!AS6 -> 0 | AT19: =SUM(E19:AR19) -> 0
B20: 15 | D20: Harry H. | E20: ='Tore (2)'!E19 -> 0 | F20: ='Tore (2)'!F19 -> 0 | G20: ='Tore (2)'!G19 -> 0 | H20: ='Tore (2)'!H19 -> 0 | I20: ='Tore (2)'!I19 -> 0 | J20: ='Tore (2)'!J19 -> 0 | K20: ='Tore (2)'!K19 -> 0 | L20: ='Tore (2)'!L19 -> 0 | ... T20: ='Tore (2)'!T19 -> 0 | U20: 0 | V20: ='Tore (2)'!V19 -> 0 | W20: ='Tore (2)'!W19 -> 0 | X20: ='Tore (2)'!X19 -> 0 | Y20: ='Tore (2)'!Y19 -> 0 | Z20: ='Tore (2)'!Z19 -> 0 | AA20: 0 | AB20: 0 | AC20: ='Tore (2)'!AC19 -> 0 | AD20: ='Tore (2)'!AD19 -> 0 | AE20: 0 | AF20: ='Tore (2)'!AF19 -> 0 | AG20: 0 | AH20: 0 | AI20: ='Tore (2)'!AI19 -> 0 | AJ20: 0 | AK20: 0 | AL20: 0 | AM20: ='Tore (2)'!AM19 -> 0 | AN20: ='Tore (2)'!AN19 -> 0 | AO20: ='Tore (2)'!AO19 -> 0 | AP20: ='Tore (2)'!AP19 -> 0 | AQ20: ='Tore (2)'!AQ19 -> 0 | AR20: ='Tore (2)'!AR19 -> 0 | AS20: ='Tore (2)'!AS19 -> 0 | AT20: =SUM(E20:AR20) -> 0
B21: 16 | D21: Walter | E21: ='Tore (2)'!E14 -> 0 | F21: ='Tore (2)'!F14 -> 0 | G21: 0 | H21: ='Tore (2)'!H14 -> 0 | I21: ='Tore (2)'!I14 -> 0 | J21: ='Tore (2)'!J14 -> 0 | K21: ='Tore (2)'!K14 -> 0 | L21: ='Tore (2)'!L14 -> 0 | M21: ='Tore (2)'!M14 -> 0 | N21: ='Tore (2)'!N14 -> 0 | O21: ='Tore (2)'!O14 -> 0 | ... Z21: ='Tore (2)'!Z14 -> 0 | AA21: 0 | AB21: 0 | AC21: ='Tore (2)'!AC14 -> 0 | AD21: ='Tore (2)'!AD14 -> 0 | AE21: ='Tore (2)'!AE14 -> 0 | AF21: ='Tore (2)'!AF14 -> 0 | AG21: ='Tore (2)'!AG14 -> 0 | AH21: 0 | AI21: ='Tore (2)'!AI14 -> 0 | AJ21: ='Tore (2)'!AJ14 -> 0 | AK21: ='Tore (2)'!AK14 -> 0 | AL21: ='Tore (2)'!AL14 -> 0 | AM21: ='Tore (2)'!AM14 -> 0 | AN21: ='Tore (2)'!AN14 -> 0 | AO21: ='Tore (2)'!AO14 -> 0 | AP21: ='Tore (2)'!AP14 -> 0 | ... AS21: ='Tore (2)'!AS14 -> 0 | AT21: =SUM(E21:AR21) -> 0
B22: 17 | D22: Viktor | E22: 0 | F22: ='Tore (2)'!F8 -> 0 | G22: 0 | H22: ='Tore (2)'!H8 -> 0 | I22: 0 | J22: ='Tore (2)'!J8 -> 0 | K22: ='Tore (2)'!K8 -> 0 | L22: ='Tore (2)'!L8 -> 0 | M22: ='Tore (2)'!M8 -> 0 | N22: ='Tore (2)'!N8 -> 0 | O22: 0 | P22: ='Tore (2)'!P8 -> 0 | Q22: 0 | R22: 0 | S22: 0 | T22: 0 | U22: 0 | V22: 0 | W22: ='Tore (2)'!W8 -> 0 | X22: 0 | Y22: 0 | Z22: ='Tore (2)'!Z8 -> 0 | AA22: ='Tore (2)'!AA8 -> 0 | AB22: ='Tore (2)'!AB8 -> 0 | AC22: 0 | AD22: 0 | AE22: 0 | AF22: 0 | AG22: 0 | AH22: ='Tore (2)'!AH8 -> 0 | AI22: 0 | AJ22: ='Tore (2)'!AJ8 -> 0 | AK22: ='Tore (2)'!AK8 -> 0 | AL22: 0 | AM22: 0 | AN22: ='Tore (2)'!AN8 -> 0 | AO22: ='Tore (2)'!AO8 -> 0 | AP22: ='Tore (2)'!AP8 -> 0 | AQ22: 0 | AR22: ='Tore (2)'!AR8 -> 0 | AS22: ='Tore (2)'!AS8 -> 0 | AT22: =SUM(E22:AR22) -> 0
B23: 18 | D23: Tommy | E23: ='Tore (2)'!E22 -> 0 | F23: ='Tore (2)'!F22 -> 0 | G23: ='Tore (2)'!G22 -> 0 | H23: ='Tore (2)'!H22 -> 0 | I23: ='Tore (2)'!I22 -> 0 | J23: ='Tore (2)'!J22 -> 0 | K23: ='Tore (2)'!K22 -> 0 | L23: ='Tore (2)'!L22 -> 0 | ... U23: ='Tore (2)'!U22 -> 0 | V23: 0 | W23: ='Tore (2)'!W22 -> 0 | X23: ='Tore (2)'!X22 -> 0 | Y23: ='Tore (2)'!Y22 -> 0 | Z23: ='Tore (2)'!Z22 -> 0 | AA23: ='Tore (2)'!AA22 -> 0 | AB23: ='Tore (2)'!AB22 -> 0 | AC23: ='Tore (2)'!AC22 -> 0 | AD23: ='Tore (2)'!AD22 -> 0 | ... AS23: ='Tore (2)'!AS22 -> 0 | AT23: =SUM(E23:AR23) -> 0
B24: 19 | D24: Gerhard L. | E24: ='Tore (2)'!E22 -> 0 | F24: ='Tore (2)'!F22 -> 0 | G24: ='Tore (2)'!G22 -> 0 | H24: ='Tore (2)'!H22 -> 0 | I24: ='Tore (2)'!I22 -> 0 | J24: ='Tore (2)'!J22 -> 0 | K24: ='Tore (2)'!K22 -> 0 | L24: ='Tore (2)'!L22 -> 0 | ... R24: ='Tore (2)'!R22 -> 0 | S24: 0 | T24: ='Tore (2)'!T22 -> 0 | U24: ='Tore (2)'!U22 -> 0 | V24: 0 | W24: ='Tore (2)'!W22 -> 0 | X24: ='Tore (2)'!X22 -> 0 | Y24: ='Tore (2)'!Y22 -> 0 | Z24: ='Tore (2)'!Z22 -> 0 | AA24: ='Tore (2)'!AA22 -> 0 | AB24: ='Tore (2)'!AB22 -> 0 | AC24: ='Tore (2)'!AC22 -> 0 | AD24: ='Tore (2)'!AD22 -> 0 | ... AG24: ='Tore (2)'!AG22 -> 0 | AH24: 0 | AI24: ='Tore (2)'!AI22 -> 0 | AJ24: ='Tore (2)'!AJ22 -> 0 | AK24: ='Tore (2)'!AK22 -> 0 | AL24: ='Tore (2)'!AL22 -> 0 | AM24: ='Tore (2)'!AM22 -> 0 | AN24: ='Tore (2)'!AN22 -> 0 | AO24: ='Tore (2)'!AO22 -> 0 | AP24: ='Tore (2)'!AP22 -> 0 | ... AS24: ='Tore (2)'!AS22 -> 0 | AT24: =SUM(E24:AR24) -> 0
B26: Saison | E26: Tore | F26: Sp | G26: T/Sp | H26: Zeit | I26: Min | S26: gespielt: | AR26: Summe: | AT26: =SUM(AT6:AT24)+AU26 -> 229 | AU26: =SUM(AU6:AU24) -> 5
B27: 2004/2005 | E27: 223 | F27: 40 | G27: 5.58 | H27: =F27*60 -> 2400 | I27: 10.8 | S27: zu 7 | T27: 2
B28: 2005/2006 | E28: 210 | F28: 40 | G28: 5.25 | H28: =F28*60 -> 2400 | I28: 11.4 | S28: zu 8 | T28: 3
B29: 2006/2007 | E29: 160 | F29: 36 | G29: 4.44 | H29: =F29*60 -> 2160 | I29: 13.5 | S29: zu 9 | T29: 7
B30: 2007/2008 | E30: 219 | F30: 39 | G30: 5.62 | H30: =F30*60 -> 2340 | I30: 10.7 | S30: zu 10 | T30: 12
B31: 2008/2009 | E31: 261 | F31: 41 | G31: 6.37 | H31: =F31*60 -> 2460 | I31: 9.4 | S31: zu 11 | T31: 11
B32: 2009/2010 | E32: 191 | F32: 40 | G32: 4.78 | H32: =F32*60 -> 2400 | I32: 12.6 | S32: zu 12 | T32: 3
B33: 2010/2011 | E33: 158 | F33: 38 | G33: 4.16 | H33: =F33*60 -> 2280 | I33: 14.4 | S33: zu 13 | T33: 2
B34: 2011/2012 | E34: 140 | F34: 37 | G34: 3.78 | H34: =F34*60 -> 2220 | I34: 15.8 | S34: zu 14
B35: 2012/2013 | E35: 187 | F35: 39 | G35: 4.79 | H35: =F35*60 -> 2340 | I35: 12.5 | S35: zu 15
B36: 2013/2014 | E36: 150 | F36: 41 | G36: 3.66 | H36: =F36*60 -> 2460 | I36: 16.4 | S36: zu 16
B37: 2014/2015 | E37: 138 | F37: 38 | G37: 3.63 | H37: =F37*60 -> 2280 | I37: 16.5 | T37: =SUM(T27:T36) -> 40
B38: 2015/2016 | E38: 120 | F38: 40 | G38: 3 | H38: =F38*60 -> 2400 | I38: 20
B39: 2016/2017 | E39: 135 | F39: 37 | G39: =E39/F39 -> 3.6486486 | H39: =F39*60 -> 2220 | I39: 16.4
B40: 2017/2018 | E40: 101 | F40: 38 | G40: =E40/F40 -> 2.6578947 | H40: =F40*60 -> 2280 | I40: =H40/E40 -> 22.574257 | K40: Unterzahl | S40: Insgesamt Unentschieden | X40: 3
B41: 2018/2019 | E41: 137 | F41: 40 | G41: =E41/F41 -> 3.425 | H41: =F41*60 -> 2400 | I41: =H41/E41 -> 17.518248 | K41: Unterzahl / Gewonnen | O41: 8 | S41: 1 Tor Differenz | X41: 11
B42: 2019/2020 | E42: 93 | F42: 25 | G42: =E42/F42 -> 3.72 | H42: 1500 | I42: =H42/E42 -> 16.129032 | K42: Unterzahl / Verloren | O42: 13 | S42: Spielausgang zu 0 | X42: 7
B43: 2020/2021 | E43: 32 | F43: 11 | G43: =E43/F43 -> 2.9090909 | H43: 660 | I43: =H43/E43 -> 20.625 | K43: Unterzahl / Unentschieden | O43: 1 | S43: Höchster Sieg : Höchste Niederlage | X43: 10:2
B44: 2021/2022 | E44: 123 | F44: 29 | G44: =E44/F44 -> 4.2413793 | H44: 1740 | I44: =H44/E44 -> 14.146341 | O44: =SUM(O41:O43) -> 22 | S44: Meisten Tore in einem Spiel | X44: 12
...

Sheet Tore (2)
E4: 1 | F4: 2 | G4: 3 | H4: 4 | I4: 5 | J4: 6 | K4: 7 | L4: 8 | M4: 9 | N4: 10 | O4: 11 | P4: 12 | Q4: 13 | R4: 14 | S4: 15 | T4: 16 | U4: 17 | V4: 18 | W4: 19 | X4: 20 | Y4: 21 | Z4: 22 | AA4: 23 | AB4: 24 | AC4: 25 | AD4: 26 | AE4: 27 | AF4: 28 | AG4: 29 | AH4: 30 | AI4: 31 | AJ4: 32 | AK4: 33 | AL4: 34 | AM4: 35 | AN4: 36 | AO4: 37 | AP4: 38 | AQ4: 39 | AR4: 40 | AS4: 41
B5: Rg | E5: =Spiele!D5 -> 45538 | F5: =Spiele!E5 -> 45545 | G5: =Spiele!F5 -> 45552 | H5: =Spiele!G5 -> 45559 | I5: =Spiele!H5 -> 45566 | J5: =Spiele!I5 -> 45573 | K5: =Spiele!J5 -> 45580 | L5: =Spiele!K5 -> 45587 | ... AR5: =Spiele!AQ5 -> 45832 | AT5: Tore | AU5: ET | AV5: Spiele | AW5: T/Spiel
B6: 1 | D6: Andi | AT6: =SUM(E6:AR6) -> 0 | AV6: =Spiele!AS6 -> 0 | AW6: =AT6/AV6 -> #DIV/0!
B7: 2 | D7: Andi K. | H7: 1 | M7: 1 | N7: 1 | U7: 2 | V7: 1 | W7: 1 | Z7: 1 | AD7: 2 | AH7: 3 | AI7: 1 | AJ7: 2 | AN7: 2 | AQ7: 2 | AT7: =SUM(E7:AR7) -> 20 | AU7: 1 | AV7: =Spiele!AS7 -> 30 | AW7: =AT7/AV7 -> 0.66666667
B8: 3 | D8: Alex | E8: 1 | G8: 4 | O8: 1 | Q8: 2 | R8: 2 | S8: 2 | T8: 2 | U8: 1 | V8: 2 | X8: 3 | Y8: 4 | AD8: 1 | AE8: 1 | AF8: 1 | AG8: 2 | AL8: 1 | AM8: 2 | AQ8: 1 | AT8: =SUM(E8:AR8) -> 33 | AV8: =Spiele!AS24 -> 31 | AW8: =AT8/AV8 -> 1.0645161
B9: 4 | D9: Berni | E9: 1 | S9: 1 | U9: 2 | AA9: 2 | AC9: 2 | AE9: 2 | AF9: 1 | AI9: 3 | AQ9: 1 | AR9: 1 | AT9: =SUM(E9:AR9) -> 16 | AV9: =Spiele!AS9 -> 21 | AW9: =AT9/AV9 -> 0.76190476
B10: 5 | D10: Franz | I10: 1 | L10: 1 | O10: 1 | T10: 2 | W10: 2 | X10: 2 | Y10: 1 | Z10: 1 | AA10: 1 | AB10: 2 | AC10: 1 | AD10: 1 | AF10: 2 | AI10: 1 | AO10: 2 | AR10: 1 | AT10: =SUM(E10:AR10) -> 22 | AV10: =Spiele!AS10 -> 36 | AW10: =AT10/AV10 -> 0.61111111
B11: 6 | D11: Gerald | K11: 1 | M11: 1 | AB11: 1 | AF11: 1 | AT11: =SUM(E11:AR11) -> 4 | AU11: 1 | AV11: =Spiele!AS11 -> 31 | AW11: =AT11/AV11 -> 0.12903226
B12: 7 | D12: Gerhard C. | E12: 1 | I12: 2 | J12: 1 | K12: 1 | L12: 1 | M12: 1 | O12: 1 | P12: 1 | R12: 1 | U12: 2 | Y12: 1 | AA12: 4 | AB12: 3 | AC12: 1 | AD12: 1 | AF12: 2 | AK12: 1 | AM12: 2 | AN12: 1 | AP12: 1 | AQ12: 1 | AT12: =SUM(E12:AR12) -> 30 | AV12: =Spiele!AS12 -> 33 | AW12: =AT12/AV12 -> 0.90909091
B13: 8 | D13: Gerhard L. | AT13: =SUM(E13:AR13) -> 0 | AV13: =Spiele!AS13 -> 0 | AW13: =AT13/AV13 -> #DIV/0!
B14: 9 | D14: Harry H. | AT14: =SUM(E14:AR14) -> 0 | AV14: =Spiele!AS14 -> 0 | AW14: =AT14/AV14 -> #DIV/0!
B15: 10 | D15: Harry S. | Y15: 1 | AT15: =SUM(E15:AR15) -> 1 | AV15: =Spiele!AS15 -> 21 | AW15: =AT15/AV15 -> 0.047619048
B16: 11 | D16: Harry Sch. | H16: 1 | I16: 2 | J16: 2 | L16: 1 | T16: 1 | X16: 4 | Y16: 1 | AB16: 2 | AE16: 3 | AK16: 1 | AM16: 2 | AR16: 2 | AT16: =SUM(E16:AR16) -> 22 | AU16: 1 | AV16: =Spiele!AS16 -> 37 | AW16: =AT16/AV16 -> 0.59459459
B17: 12 | D17: Lukas | G17: 1 | H17: 1 | M17: 1 | S17: 1 | T17: 1 | W17: 1 | Z17: 2 | AB17: 1 | AD17: 1 | AH17: 2 | AK17: 1 | AT17: =SUM(E17:AR17) -> 13 | AU17: 1 | AV17: =Spiele!AS17 -> 29 | AW17: =AT17/AV17 -> 0.44827586
B18: 13 | D18: Martin | E18: 1 | G18: 2 | H18: 1 | K18: 1 | L18: 1 | AK18: 2 | AM18: 1 | AN18: 2 | AO18: 1 | AP18: 2 | AR18: 1 | AT18: =SUM(E18:AR18) -> 15 | AV18: =Spiele!AS18 -> 0 | AW18: =AT18/AV18 -> #DIV/0!
B19: 14 | D19: Christoph | AT19: =SUM(E19:AR19) -> 0 | AV19: =Spiele!AS19 -> 22 | AW19: =AT19/AV19 -> 0
B20: 15 | D20: Thomas | F20: 1 | J20: 1 | K20: 2 | L20: 1 | O20: 1 | Q20: 1 | T20: 1 | Y20: 1 | AD20: 1 | AQ20: 2 | AT20: =SUM(E20:AR20) -> 12 | AV20: =Spiele!AS20 -> 0 | AW20: =AT20/AV20 -> #DIV/0!
B21: 16 | D21: Tommy | AT21: =SUM(E21:AR21) -> 0 | AV21: =Spiele!AS21 -> 34 | AW21: =AT21/AV21 -> 0
B22: 17 | D22: Viktor | AT22: =SUM(E22:AR22) -> 0 | AV22: =Spiele!AS22 -> 13 | AW22: =AT22/AV22 -> 0
B23: 18 | D23: Walter | AT23: =SUM(E23:AR23) -> 0 | AV23: =Spiele!AS23 -> 16
B24: 19 | D24: Mario | G24: 2 | H24: 1 | I24: 2 | J24: 1 | M24: 2 | P24: 1 | Q24: 2 | AE24: 1 | AF24: 1 | AJ24: 1 | AL24: 1 | AM24: 1 | AQ24: 2 | AT24: =SUM(E24:AR24) -> 18 | AU24: 1 | AV24: =Spiele!AS25 -> 25
B25: 20 | D25: Niki | G25: 1 | J25: 1 | P25: 1 | U25: 1 | X25: 3 | Y25: 1 | AA25: 3 | AB25: 1 | AG25: 2 | AH25: 1 | AK25: 3 | AT25: =SUM(E25:AR25) -> 18 | AV25: =Spiele!AS26 -> 23
AR27: Summe: | AT27: =SUM(AT6:AT25)+AU27 -> 229 | AU27: =SUM(AU6:AU25) -> 5

Sheet Spiele
D4: 1 | E4: 2 | F4: 3 | G4: 4 | H4: 5 | I4: 6 | J4: 7 | K4: 8 | L4: 9 | M4: 10 | N4: 11 | O4: 12 | P4: 13 | Q4: 14 | R4: 15 | S4: 16 | T4: 17 | U4: 18 | V4: 19 | W4: 20 | X4: 21 | Y4: 22 | Z4: 23 | AA4: 24 | AB4: 25 | AC4: 26 | AD4: 27 | AE4: 28 | AF4: 29 | AG4: 30 | AH4: 31 | AI4: 32 | AJ4: 33 | AK4: 34 | AL4: 35 | AM4: 36 | AN4: 37 | AO4: 38 | AP4: 39 | AQ4: 40
B5: Rg | D5: 45538 | E5: 45545 | F5: 45552 | G5: 45559 | H5: 45566 | I5: 45573 | J5: 45580 | K5: 45587 | L5: 45594 | M5: 45601 | N5: 45608 | O5: 45615 | P5: 45622 | Q5: 45629 | R5: 45643 | S5: 45664 | T5: 45671 | U5: 45678 | V5: 45685 | W5: 45692 | X5: 45699 | Y5: 45706 | Z5: 45713 | AA5: 45720 | AB5: 45727 | AC5: 45734 | AD5: 45741 | AE5: 45748 | AF5: 45755 | AG5: 45762 | AH5: 45769 | AI5: 45776 | AJ5: 45783 | AK5: 45790 | AL5: 45797 | AM5: 45804 | AN5: 45811 | AO5: 45818 | AP5: 45825 | AQ5: 45832 | AR5: Pkt | AS5: Spiele | AT5: A | AU5: Pkt/Sp+A | AW5: S | AX5: U | AY5: N
B6: 1 | C6: Andi | D6: =IF(OR(Begegnungen!$C$3=$C$6,Begegnungen!$C$4=$C$6,Begegnungen!$C$5=$C$6,Begegnungen!$C$6=$C$6,Begegnungen!$C$7=$C$6,Begegnungen!$C$8=$C$6,Begegnungen!$C$9=$C$6),Begegnungen!$C$16,IF(OR(Begegnungen!$E$3=$C$6,Begegnungen!$E$4=$C$6,Begegnungen!$E$5=$C$6,Begegnungen!$E$6=$C$6,Begegnungen!$E$7=$C$6,Begegnungen!$E$8=$C$6,Begegnungen!$E$9=$C$6),Begegnungen!$E$16,"")) | E6: =IF(OR(Begegnungen!$I$3=C6,Begegnungen!$I$4=C6,Begegnungen!$I$5=C6,Begegnungen!$I$6=C6,Begegnungen!$I$7=C6,Begegnungen!$I$8=C6,Begegnungen!$I$9=C6),Begegnungen!$I$16,IF(OR(Begegnungen!$K$3=C6,Begegnungen!$K$4=C6,Begegnungen!$K$5=C6,Begegnungen!$K$6=C6,Begegnungen!$K$7=C6,Begegnungen!$K$8=C6,Begegnungen!$K$9=C6),Begegnungen!$K$16,"")) | F6: =IF(OR(Begegnungen!$C$19=C6,Begegnungen!$C$20=C6,Begegnungen!$C$21=C6,Begegnungen!$C$22=C6,Begegnungen!$C$23=C6,Begegnungen!$C$24=C6,Begegnungen!$C$25=C6),Begegnungen!$C$32,IF(OR(Begegnungen!$E$19=C6,Begegnungen!$E$20=C6,Begegnungen!$E$21=C6,Begegnungen!$E$22=C6,Begegnungen!$E$23=C6,Begegnungen!$E$24=C6,Begegnungen!$E$25=C6),Begegnungen!$E$32,"")) | G6: =IF(OR(Begegnungen!$I$19=C6,Begegnungen!$I$20=C6,Begegnungen!$I$21=C6,Begegnungen!$I$22=C6,Begegnungen!$I$23=C6,Begegnungen!$I$24=C6,Begegnungen!$I$25=C6),Begegnungen!$I$32,IF(OR(Begegnungen!$K$19=C6,Begegnungen!$K$20=C6,Begegnungen!$K$21=C6,Begegnungen!$K$22=C6,Begegnungen!$K$23=C6,Begegnungen!$K$24=C6,Begegnungen!$K$25=C6),Begegnungen!$K$32,"")) | H6: =IF(OR(Begegnungen!$C$35=C6,Begegnungen!$C$36=C6,Begegnungen!$C$37=C6,Begegnungen!$C$38=C6,Begegnungen!$C$39=C6,Begegnungen!$C$40=C6,Begegnungen!$C$41=C6),Begegnungen!$C$49,IF(OR(Begegnungen!$E$35=C6,Begegnungen!$E$36=C6,Begegnungen!$E$37=C6,Begegnungen!$E$38=C6,Begegnungen!$E$39=C6,Begegnungen!$E$40=C6,Begegnungen!$E$41=C6),Begegnungen!$E$49,"")) | I6: =IF(OR(Begegnungen!$I$35=C6,Begegnungen!$I$36=C6,Begegnungen!$I$37=C6,Begegnungen!$I$38=C6,Begegnungen!$I$39=C6,Begegnungen!$I$40=C6,Begegnungen!$I$41=C6),Begegnungen!$I$49,IF(OR(Begegnungen!$K$35=C6,Begegnungen!$K$36=C6,Begegnungen!$K$37=C6,Begegnungen!$K$38=C6,Begegnungen!$K$39=C6,Begegnungen!$K$40=C6,Begegnungen!$K$41=C6),Begegnungen!$K$49,"")) | J6: =IF(OR(Begegnungen!$C$52=C6,Begegnungen!$C$53=C6,Begegnungen!$C$54=C6,Begegnungen!$C$55=C6,Begegnungen!$C$56=C6,Begegnungen!$C$57=C6,Begegnungen!$C$58=C6),Begegnungen!$C$65,IF(OR(Begegnungen!$E$52=C6,Begegnungen!$E$53=C6,Begegnungen!$E$54=C6,Begegnungen!$E$55=C6,Begegnungen!$E$56=C6,Begegnungen!$E$57=C6,Begegnungen!$E$58=C6),Begegnungen!$E$65,"")) | K6: =IF(OR(Begegnungen!$I$52=C6,Begegnungen!$I$53=C6,Begegnungen!$I$54=C6,Begegnungen!$I$55=C6,Begegnungen!$I$56=C6,Begegnungen!$I$57=C6,Begegnungen!$I$58=C6),Begegnungen!$I$65,IF(OR(Begegnungen!$K$52=C6,Begegnungen!$K$53=C6,Begegnungen!$K$54=C6,Begegnungen!$K$55=C6,Begegnungen!$K$56=C6,Begegnungen!$K$57=C6,Begegnungen!$K$58=C6),Begegnungen!$K$65,"")) | L6: =IF(OR(Begegnungen!$C$68=C6,Begegnungen!$C$69=C6,Begegnungen!$C$70=C6,Begegnungen!$C$71=C6,Begegnungen!$C$72=C6,Begegnungen!$C$73=C6,Begegnungen!$C$74=C6),Begegnungen!$C$81,IF(OR(Begegnungen!$E$68=C6,Begegnungen!$E$69=C6,Begegnungen!$E$70=C6,Begegnungen!$E$71=C6,Begegnungen!$E$72=C6,Begegnungen!$E$73=C6,Begegnungen!$E$74=C6),Begegnungen!$E$81,"")) | M6: =IF(OR(Begegnungen!$I$68=C6,Begegnungen!$I$69=C6,Begegnungen!$I$70=C6,Begegnungen!$I$71=C6,Begegnungen!$I$72=C6,Begegnungen!$I$73=C6,Begegnungen!$I$74=C6),Begegnungen!$I$81,IF(OR(Begegnungen!$K$68=C6,Begegnungen!$K$69=C6,Begegnungen!$K$70=C6,Begegnungen!$K$71=C6,Begegnungen!$K$72=C6,Begegnungen!$K$73=C6,Begegnungen!$K$74=C6),Begegnungen!$K$81,"")) | N6: =IF(OR(Begegnungen!$C$84=C6,Begegnungen!$C$85=C6,Begegnungen!$C$86=C6,Begegnungen!$C$87=C6,Begegnungen!$C$88=C6,Begegnungen!$C$89=C6,Begegnungen!$C$90=C6),Begegnungen!$C$98,IF(OR(Begegnungen!$E$84=C6,Begegnungen!$E$85=C6,Begegnungen!$E$86=C6,Begegnungen!$E$87=C6,Begegnungen!$E$88=C6,Begegnungen!$E$89=C6,Begegnungen!$E$90=C6),Begegnungen!$E$98,"")) | O6: =IF(OR(Begegnungen!$I$84=C6,Begegnungen!$I$85=C6,Begegnungen!$I$86=C6,Begegnungen!$I$87=C6,Begegnungen!$I$88=C6,Begegnungen!$I$89=C6,Begegnungen!$I$90=C6),Begegnungen!$I$98,IF(OR(Begegnungen!$K$84=C6,Begegnungen!$K$85=C6,Begegnungen!$K$86=C6,Begegnungen!$K$87=C6,Begegnungen!$K$88=C6,Begegnungen!$K$89=C6,Begegnungen!$K$90=C6),Begegnungen!$K$98,"")) | Q6: =IF(OR(Begegnungen!$I$101=C6,Begegnungen!$I$102=C6,Begegnungen!$I$103=C6,Begegnungen!$I$104=C6,Begegnungen!$I$105=C6,Begegnungen!$I$106=C6,Begegnungen!$I$107=C6),Begegnungen!$I$114,IF(OR(Begegnungen!$K$101=C6,Begegnungen!$K$102=C6,Begegnungen!$K$103=C6,Begegnungen!$K$104=C6,Begegnungen!$K$105=C6,Begegnungen!$K$106=C6,Begegnungen!$K$107=C6),Begegnungen!$K$114,"")) | R6: =IF(OR(Begegnungen!$C$117=C6,Begegnungen!$C$118=C6,Begegnungen!$C$119=C6,Begegnungen!$C$120=C6,Begegnungen!$C$121=C6,Begegnungen!$C$122=C6,Begegnungen!$C$123=C6),Begegnungen!$C$130,IF(OR(Begegnungen!$E$117=C6,Begegnungen!$E$118=C6,Begegnungen!$E$119=C6,Begegnungen!$E$120=C6,Begegnungen!$E$121=C6,Begegnungen!$E$122=C6,Begegnungen!$E$123=C6),Begegnungen!$E$130,"")) | S6: =IF(OR(Begegnungen!$I$117=C6,Begegnungen!$I$118=C6,Begegnungen!$I$119=C6,Begegnungen!$I$120=C6,Begegnungen!$I$121=C6,Begegnungen!$I$122=C6,Begegnungen!$I$123=C6),Begegnungen!$I$130,IF(OR(Begegnungen!$K$117=C6,Begegnungen!$K$118=C6,Begegnungen!$K$119=C6,Begegnungen!$K$120=C6,Begegnungen!$K$121=C6,Begegnungen!$K$122=C6,Begegnungen!$K$123=C6),Begegnungen!$K$130,"")) | T6: =IF(OR(Begegnungen!$C$133=C6,Begegnungen!$C$134=C6,Begegnungen!$C$135=C6,Begegnungen!$C$136=C6,Begegnungen!$C$137=C6,Begegnungen!$C$138=C6,Begegnungen!$C$139=C6),Begegnungen!$C$146,IF(OR(Begegnungen!$E$133=C6,Begegnungen!$E$134=C6,Begegnungen!$E$135=C6,Begegnungen!$E$136=C6,Begegnungen!$E$137=C6,Begegnungen!$E$138=C6,Begegnungen!$E$139=C6),Begegnungen!$E$146,"")) | U6: =IF(OR(Begegnungen!$I$133=C6,Begegnungen!$I$134=C6,Begegnungen!$I$135=C6,Begegnungen!$I$136=C6,Begegnungen!$I$137=C6,Begegnungen!$I$138=C6,Begegnungen!$I$139=C6),Begegnungen!$I$146,IF(OR(Begegnungen!$K$133=C6,Begegnungen!$K$134=C6,Begegnungen!$K$135=C6,Begegnungen!$K$136=C6,Begegnungen!$K$137=C6,Begegnungen!$K$138=C6,Begegnungen!$K$139=C6),Begegnungen!$K$146,"")) | V6: =IF(OR(Begegnungen!$C$149=C6,Begegnungen!$C$150=C6,Begegnungen!$C$151=C6,Begegnungen!$C$152=C6,Begegnungen!$C$153=C6,Begegnungen!$C$154=C6,Begegnungen!$C$155=C6),Begegnungen!$C$162,IF(OR(Begegnungen!$E$149=C6,Begegnungen!$E$150=C6,Begegnungen!$E$151=C6,Begegnungen!$E$152=C6,Begegnungen!$E$153=C6,Begegnungen!$E$154=C6,Begegnungen!$E$155=C6),Begegnungen!$E$162,"")) | W6: =IF(OR(Begegnungen!$I$149=C6,Begegnungen!$I$150=C6,Begegnungen!$I$151=C6,Begegnungen!$I$152=C6,Begegnungen!$I$153=C6,Begegnungen!$I$154=C6,Begegnungen!$I$155=C6),Begegnungen!$I$162,IF(OR(Begegnungen!$K$149=C6,Begegnungen!$K$150=C6,Begegnungen!$K$151=C6,Begegnungen!$K$152=C6,Begegnungen!$K$153=C6,Begegnungen!$K$154=C6,Begegnungen!$K$155=C6),Begegnungen!$K$162,"")) | Y6: =IF(OR(Begegnungen!$I$165=C6,Begegnungen!$I$166=C6,Begegnungen!$I$167=C6,Begegnungen!$I$168=C6,Begegnungen!$I$169=C6,Begegnungen!$I$170=C6,Begegnungen!$I$171=C6),Begegnungen!$I$178,IF(OR(Begegnungen!$K$165=C6,Begegnungen!$K$166=C6,Begegnungen!$K$167=C6,Begegnungen!$K$168=C6,Begegnungen!$K$169=C6,Begegnungen!$K$170=C6,Begegnungen!$K$171=C6),Begegnungen!$K$178,"")) | Z6: =IF(OR(Begegnungen!$C$181=C6,Begegnungen!$C$182=C6,Begegnungen!$C$183=C6,Begegnungen!$C$184=C6,Begegnungen!$C$185=C6,Begegnungen!$C$186=C6,Begegnungen!$C$187=C6),Begegnungen!$C$194,IF(OR(Begegnungen!$E$181=C6,Begegnungen!$E$182=C6,Begegnungen!$E$183=C6,Begegnungen!$E$184=C6,Begegnungen!$E$185=C6,Begegnungen!$E$186=C6,Begegnungen!$E$187=C6),Begegnungen!$E$194,"")) | AA6: =IF(OR(Begegnungen!$I$181=C6,Begegnungen!$I$182=C6,Begegnungen!$I$183=C6,Begegnungen!$I$184=C6,Begegnungen!$I$185=C6,Begegnungen!$I$186=C6,Begegnungen!$I$187=C6),Begegnungen!$I$194,IF(OR(Begegnungen!$K$181=C6,Begegnungen!$K$182=C6,Begegnungen!$K$183=C6,Begegnungen!$K$184=C6,Begegnungen!$K$185=C6,Begegnungen!$K$186=C6,Begegnungen!$K$187=C6),Begegnungen!$K$194,"")) | AB6: =IF(OR(Begegnungen!$C$197=C6,Begegnungen!$C$198=C6,Begegnungen!$C$199=C6,Begegnungen!$C$200=C6,Begegnungen!$C$201=C6,Begegnungen!$C$202=C6,Begegnungen!$C$203=C6),Begegnungen!$C$210,IF(OR(Begegnungen!$E$197=C6,Begegnungen!$E$198=C6,Begegnungen!$E$199=C6,Begegnungen!$E$200=C6,Begegnungen!$E$201=C6,Begegnungen!$E$202=C6,Begegnungen!$E$203=C6),Begegnungen!$E$210,"")) | AC6: =IF(OR(Begegnungen!$I$197=C6,Begegnungen!$I$198=C6,Begegnungen!$I$199=C6,Begegnungen!$I$200=C6,Begegnungen!$I$201=C6,Begegnungen!$I$202=C6,Begegnungen!$I$203=C6),Begegnungen!$I$210,IF(OR(Begegnungen!$K$197=C6,Begegnungen!$K$198=C6,Begegnungen!$K$199=C6,Begegnungen!$K$200=C6,Begegnungen!$K$201=C6,Begegnungen!$K$202=C6,Begegnungen!$K$203=C6),Begegnungen!$K$210,"")) | AD6: =IF(OR(Begegnungen!$C$213=C6,Begegnungen!$C$214=C6,Begegnungen!$C$215=C6,Begegnungen!$C$216=C6,Begegnungen!$C$217=C6,Begegnungen!$C$218=C6,Begegnungen!$C$219=C6),Begegnungen!$C$226,IF(OR(Begegnungen!$E$213=C6,Begegnungen!$E$214=C6,Begegnungen!$E$215=C6,Begegnungen!$E$216=C6,Begegnungen!$E$217=C6,Begegnungen!$E$218=C6,Begegnungen!$E$219=C6),Begegnungen!$E$226,"")) | AE6: =IF(OR(Begegnungen!$I$213=C6,Begegnungen!$I$214=C6,Begegnungen!$I$215=C6,Begegnungen!$I$216=C6,Begegnungen!$I$217=C6,Begegnungen!$I$218=C6,Begegnungen!$I$219=C6),Begegnungen!$I$226,IF(OR(Begegnungen!$K$213=C6,Begegnungen!$K$214=C6,Begegnungen!$K$215=C6,Begegnungen!$K$216=C6,Begegnungen!$K$217=C6,Begegnungen!$K$218=C6,Begegnungen!$K$219=C6),Begegnungen!$K$226,"")) | AF6: =IF(OR(Begegnungen!$C$229=C6,Begegnungen!$C$230=C6,Begegnungen!$C$231=C6,Begegnungen!$C$232=C6,Begegnungen!$C$233=C6,Begegnungen!$C$234=C6,Begegnungen!$C$235=C6),Begegnungen!$C$242,IF(OR(Begegnungen!$E$229=C6,Begegnungen!$E$230=C6,Begegnungen!$E$231=C6,Begegnungen!$E$232=C6,Begegnungen!$E$233=C6,Begegnungen!$E$234=C6,Begegnungen!$E$235=C6),Begegnungen!$E$242,"")) | AG6: =IF(OR(Begegnungen!$I$229=C6,Begegnungen!$I$230=C6,Begegnungen!$I$231=C6,Begegnungen!$I$232=C6,Begegnungen!$I$233=C6,Begegnungen!$I$234=C6,Begegnungen!$I$235=C6),Begegnungen!$I$242,IF(OR(Begegnungen!$K$229=C6,Begegnungen!$K$230=C6,Begegnungen!$K$231=C6,Begegnungen!$K$232=C6,Begegnungen!$K$233=C6,Begegnungen!$K$234=C6,Begegnungen!$K$235=C6),Begegnungen!$K$242,"")) | AH6: =IF(OR(Begegnungen!$C$245=C6,Begegnungen!$C$246=C6,Begegnungen!$C$247=C6,Begegnungen!$C$248=C6,Begegnungen!$C$249=C6,Begegnungen!$C$250=C6,Begegnungen!$C$251=C6),Begegnungen!$C$258,IF(OR(Begegnungen!$E$245=C6,Begegnungen!$E$246=C6,Begegnungen!$E$247=C6,Begegnungen!$E$248=C6,Begegnungen!$E$249=C6,Begegnungen!$E$250=C6,Begegnungen!$E$251=C6),Begegnungen!$E$258,"")) | AI6: =IF(OR(Begegnungen!$I$245=C6,Begegnungen!$I$246=C6,Begegnungen!$I$247=C6,Begegnungen!$I$248=C6,Begegnungen!$I$249=C6,Begegnungen!$I$250=C6,Begegnungen!$I$251=C6),Begegnungen!$I$258,IF(OR(Begegnungen!$K$245=C6,Begegnungen!$K$246=C6,Begegnungen!$K$247=C6,Begegnungen!$K$248=C6,Begegnungen!$K$249=C6,Begegnungen!$K$250=C6,Begegnungen!$K$251=C6),Begegnungen!$K$258,"")) | AJ6: =IF(OR(Begegnungen!$C$261=C6,Begegnungen!$C$262=C6,Begegnungen!$C$263=C6,Begegnungen!$C$264=C6,Begegnungen!$C$265=C6,Begegnungen!$C$266=C6,Begegnungen!$C$267=C6),Begegnungen!$C$274,IF(OR(Begegnungen!$E$261=C6,Begegnungen!$E$262=C6,Begegnungen!$E$263=C6,Begegnungen!$E$264=C6,Begegnungen!$E$265=C6,Begegnungen!$E$266=C6,Begegnungen!$E$267=C6),Begegnungen!$E$274,"")) | AK6: =IF(OR(Begegnungen!$I$261=C6,Begegnungen!$I$262=C6,Begegnungen!$I$263=C6,Begegnungen!$I$264=C6,Begegnungen!$I$265=C6,Begegnungen!$I$266=C6,Begegnungen!$I$267=C6),Begegnungen!$I$274,IF(OR(Begegnungen!$K$261=C6,Begegnungen!$K$262=C6,Begegnungen!$K$263=C6,Begegnungen!$K$264=C6,Begegnungen!$K$265=C6,Begegnungen!$K$266=C6,Begegnungen!$K$267=C6),Begegnungen!$K$274,"")) | AL6: =IF(OR(Begegnungen!$C$277=C6,Begegnungen!$C$278=C6,Begegnungen!$C$279=C6,Begegnungen!$C$280=C6,Begegnungen!$C$281=C6,Begegnungen!$C$282=C6,Begegnungen!$C$283=C6),Begegnungen!$C$290,IF(OR(Begegnungen!$E$277=C6,Begegnungen!$E$278=C6,Begegnungen!$E$279=C6,Begegnungen!$E$280=C6,Begegnungen!$E$281=C6,Begegnungen!$E$282=C6,Begegnungen!$E$283=C6),Begegnungen!$E$290,"")) | AM6: =IF(OR(Begegnungen!$I$277=C6,Begegnungen!$I$278=C6,Begegnungen!$I$279=C6,Begegnungen!$I$280=C6,Begegnungen!$I$281=C6,Begegnungen!$I$282=C6,Begegnungen!$I$283=C6),Begegnungen!$I$290,IF(OR(Begegnungen!$K$277=C6,Begegnungen!$K$278=C6,Begegnungen!$K$279=C6,Begegnungen!$K$280=C6,Begegnungen!$K$281=C6,Begegnungen!$K$282=C6,Begegnungen!$K$283=C6),Begegnungen!$K$290,"")) | AN6: =IF(OR(Begegnungen!$C$293=C6,Begegnungen!$C$294=C6,Begegnungen!$C$295=C6,Begegnungen!$C$296=C6,Begegnungen!$C$297=C6,Begegnungen!$C$298=C6,Begegnungen!$C$299=C6),Begegnungen!$C$306,IF(OR(Begegnungen!$E$293=C6,Begegnungen!$E$294=C6,Begegnungen!$E$295=C6,Begegnungen!$E$296=C6,Begegnungen!$E$297=C6,Begegnungen!$E$298=C6,Begegnungen!$E$299=C6),Begegnungen!$E$306,"")) | AO6: =IF(OR(Begegnungen!$I$293=C6,Begegnungen!$I$294=C6,Begegnungen!$I$295=C6,Begegnungen!$I$296=C6,Begegnungen!$I$297=C6,Begegnungen!$I$298=C6,Begegnungen!$I$299=C6),Begegnungen!$I$306,IF(OR(Begegnungen!$K$293=C6,Begegnungen!$K$294=C6,Begegnungen!$K$295=C6,Begegnungen!$K$296=C6,Begegnungen!$K$297=C6,Begegnungen!$K$298=C6,Begegnungen!$K$299=C6),Begegnungen!$K$306,"")) | AP6: =IF(OR(Begegnungen!$C$309=C6,Begegnungen!$C$310=C6,Begegnungen!$C$311=C6,Begegnungen!$C$312=C6,Begegnungen!$C$313=C6,Begegnungen!$C$314=C6,Begegnungen!$C$315=C6),Begegnungen!$C$322,IF(OR(Begegnungen!$E$309=C6,Begegnungen!$E$310=C6,Begegnungen!$E$311=C6,Begegnungen!$E$312=C6,Begegnungen!$E$313=C6,Begegnungen!$E$314=C6,Begegnungen!$E$315=C6),Begegnungen!$E$322,"")) | AQ6: =IF(OR(Begegnungen!$I$309=C6,Begegnungen!$I$310=C6,Begegnungen!$I$311=C6,Begegnungen!$I$312=C6,Begegnungen!$I$313=C6,Begegnungen!$I$314=C6,Begegnungen!$I$315=C6),Begegnungen!$I$322,IF(OR(Begegnungen!$K$309=C6,Begegnungen!$K$310=C6,Begegnungen!$K$311=C6,Begegnungen!$K$312=C6,Begegnungen!$K$313=C6,Begegnungen!$K$314=C6,Begegnungen!$K$315=C6),Begegnungen!$K$322,"")) | AR6: =AW6*3+AX6 -> 0 | AS6: =40-COUNTBLANK(D6:AQ6) -> 0 | AT6: =AS6*0.05 -> 0 | AU6: =AR6/AS6+AT6 -> #DIV/0! | AW6: =COUNTIF(D6:AQ6,3) -> 0 | AX6: =COUNTIF(D6:AQ6,1) -> 0 | AY6: =COUNTIF(D6:AQ6,0) -> 0
